<?xml version="1.0"?>

<!-- space dyn講習会 補足資料6 -->
<sdf version="1.9">
  <model name="floating_manipulator">
    <static>false</static>

    <!-- Link 0: 1700kg cube -->
    <link name="link0">
      <!--  ******************pose -->
      <pose>0 0 0 0 0 0</pose>
      <inertial>
        <mass>500</mass>
        <inertia>
          <ixx>300</ixx>
          <iyy>300</iyy>
          <izz>300</izz>
        </inertia>
      </inertial>
      <collision name="collision">
        <geometry>
          <box>
            <size>3.5 3.5 3.5</size>
          </box>
        </geometry>
      </collision>
      <visual name="visual">
        <material>
          <ambient>0.03 0.03 0.04 1</ambient>
          <diffuse>0.15 0.15 0.2 1</diffuse>
          <specular>1.0 1.0 1.0 1</specular>
        </material>
        <geometry>
          <box>
            <size>3.5 3.5 3.5</size>
          </box>
        </geometry>
      </visual>
    </link>

    <!-- Link 1:5kg, 0.25m long -->
    <link name="link1">
      <!--  ******************pose -->
      <pose>0 0 1.875 0 0 0</pose>
      <inertial>
        <!--  ******************mass -->
        <mass>5.0</mass>
        <!--  ******************inertia -->
        <inertia>
          <ixx>0.0292</ixx>
          <iyy>0.0292</iyy>
          <izz>0.00625</izz>
        </inertia>
      </inertial>
      <collision name="collision">
        <geometry>
          <!--  ******************col size -->
          <cylinder>
            <radius>0.2</radius>
            <length>0.25</length>
          </cylinder>
        </geometry>
      </collision>
      <visual name="visual">
        <material>
          <ambient>0.03 0.03 0.04 1</ambient>
          <diffuse>0.15 0.15 0.2 1</diffuse>
          <specular>1.0 1.0 1.0 1</specular>
        </material>
        <geometry>
          <!--  ******************vis size-->
          <cylinder>
            <radius>0.2</radius>
            <length>0.25</length>
          </cylinder>
        </geometry>
      </visual>
      <visual name="motor">
        <material>
          <ambient>0.03 0.03 0.04 1</ambient>
          <diffuse>0.15 0.15 0.2 1</diffuse>
          <specular>1.0 1.0 1.0 1</specular>
        </material>
        <pose>0 0 0.125 1.5707 0 0</pose>
        <geometry>
          <cylinder>
            <radius>0.2</radius>
            <length>0.4</length>
          </cylinder>
        </geometry>
      </visual>
      <visual name="zmotor">
        <material>
          <ambient>0.03 0.03 0.04 1</ambient>
          <diffuse>0.15 0.15 0.2 1</diffuse>
          <specular>1.0 1.0 1.0 1</specular>
        </material>
        <pose>0 0 -0.1 0 0 0</pose>
        <geometry>
          <cylinder>
            <radius>0.3</radius>
            <length>0.05</length>
          </cylinder>
        </geometry>
      </visual>
    </link>

    <!-- Link 1: 50, 2.5m long -->
    <link name="link2">
      <!--
      SDFの<pose>はワールド座標系での位置姿勢を指定します。link1からの相対姿勢を直接指定することはできませんが、<joint>でlink2をlink1に接続し、<pose>を使わずに相対位置は<joint>の<pose>で指定します。link2の<pose>は省略または0にしてください。-->
      <!--  ******************pose -->
      <pose>0 0 3.25 0 0 0</pose>
      <inertial>
        <!--  ******************mass -->
        <mass>50.0</mass>
        <!--  ******************inertia -->
        <inertia>
          <ixx>26.1</ixx>
          <iyy>26.1</iyy>
          <izz>0.0625</izz>
        </inertia>
      </inertial>
      <collision name="collision">
        <geometry>
          <!--  ******************col size -->
          <cylinder>
            <radius>0.2</radius>
            <length>2.5</length>
          </cylinder>
        </geometry>
      </collision>
      <visual name="visual">
        <material>
          <ambient>0.03 0.03 0.04 1</ambient>
          <diffuse>0.15 0.15 0.2 1</diffuse>
          <specular>1.0 1.0 1.0 1</specular>
        </material>
        <geometry>
          <!--  ******************vis size-->
          <cylinder>
            <radius>0.2</radius>
            <length>2.5</length>
          </cylinder>
        </geometry>
      </visual>
      <visual name="motor">
        <material>
          <ambient>0.03 0.03 0.04 1</ambient>
          <diffuse>0.15 0.15 0.2 1</diffuse>
          <specular>1.0 1.0 1.0 1</specular>
        </material>
        <pose>0 0 1.25 1.5707 0 0</pose>
        <geometry>
          <cylinder>
            <radius>0.2</radius>
            <length>0.4</length>
          </cylinder>
        </geometry>
      </visual>
    </link>

    <!-- Link 1: 50, 2.5m long -->
    <link name="link3">
      <!--
      SDFの<pose>はワールド座標系での位置姿勢を指定します。link1からの相対姿勢を直接指定することはできませんが、<joint>でlink2をlink1に接続し、<pose>を使わずに相対位置は<joint>の<pose>で指定します。link2の<pose>は省略または0にしてください。-->
      <!--  ******************pose -->
      <pose>0 0 5.75 0 0 0</pose>
      <inertial>
        <!--  ******************mass -->
        <mass>50</mass>
        <!--  ******************inertia -->
        <inertia>
          <ixx>26.1</ixx>
          <iyy>26.1</iyy>
          <izz>0.00625</izz>
        </inertia>
      </inertial>
      <collision name="collision">
        <geometry>
          <!--  ******************col size -->
          <cylinder>
            <radius>0.2</radius>
            <length>2.5</length>
          </cylinder>
        </geometry>
      </collision>
      <visual name="visual">
        <material>
          <ambient>0.03 0.03 0.04 1</ambient>
          <diffuse>0.15 0.15 0.2 1</diffuse>
          <specular>1.0 1.0 1.0 1</specular>
        </material>
        <geometry>
          <!--  ******************vis size-->
          <cylinder>
            <radius>0.2</radius>
            <length>2.5</length>
          </cylinder>
        </geometry>
      </visual>
      <visual name="motor">
        <material>
          <ambient>0.03 0.03 0.04 1</ambient>
          <diffuse>0.15 0.15 0.2 1</diffuse>
          <specular>1.0 1.0 1.0 1</specular>
        </material>
        <pose>0 0 1.25 1.5707 0 0</pose>
        <geometry>
          <cylinder>
            <radius>0.2</radius>
            <length>0.4</length>
          </cylinder>
        </geometry>
      </visual>
    </link>

    <!-- Link 1: 50, 2.5m long -->
    <link name="link4">
      <!--
      SDFの<pose>はワールド座標系での位置姿勢を指定します。link1からの相対姿勢を直接指定することはできませんが、<joint>でlink2をlink1に接続し、<pose>を使わずに相対位置は<joint>の<pose>で指定します。link2の<pose>は省略または0にしてください。-->
      <!--  ******************pose -->
      <pose>0 0 7.25 0 0 0</pose>
      <inertial>
        <!--  ******************mass -->
        <mass>10</mass>
        <!--  ******************inertia -->
        <inertia>
          <ixx>0.215</ixx>
          <iyy>0.215</iyy>
          <izz>0.0125</izz>
        </inertia>
      </inertial>
      <collision name="collision">
        <geometry>
          <!--  ******************col size -->
          <cylinder>
            <radius>0.2</radius>
            <length>0.5</length>
          </cylinder>
        </geometry>
      </collision>
      <visual name="visual">
        <material>
          <ambient>0.03 0.03 0.04 1</ambient>
          <diffuse>0.15 0.15 0.2 1</diffuse>
          <specular>1.0 1.0 1.0 1</specular>
        </material>
        <geometry>
          <!--  ******************vis size-->
          <material>
            <ambient>0.03 0.03 0.04 1</ambient>
            <diffuse>0.15 0.15 0.2 1</diffuse>
            <specular>1.0 1.0 1.0 1</specular>
          </material>
          <cylinder>
            <radius>0.2</radius>
            <length>0.5</length>
          </cylinder>
        </geometry>
      </visual>
      <visual name="motor">
        <material>
          <ambient>0.03 0.03 0.04 1</ambient>
          <diffuse>0.15 0.15 0.2 1</diffuse>
          <specular>1.0 1.0 1.0 1</specular>
        </material>
        <pose>0 0 0.25 0 1.5707 0</pose>
        <geometry>
          <cylinder>
            <radius>0.2</radius>
            <length>0.4</length>
          </cylinder>
        </geometry>
      </visual>
    </link>

    <!-- Link 1: 50, 2.5m long -->
    <link name="link5">
      <!--
      SDFの<pose>はワールド座標系での位置姿勢を指定します。link1からの相対姿勢を直接指定することはできませんが、<joint>でlink2をlink1に接続し、<pose>を使わずに相対位置は<joint>の<pose>で指定します。link2の<pose>は省略または0にしてください。-->
      <!--  ******************pose -->
      <pose>0 0 7.625 0 0 0</pose>
      <inertial>
        <!--  ******************mass -->
        <mass>5</mass>
        <!--  ******************inertia -->
        <inertia>
          <ixx>0.0292</ixx>
          <iyy>0.0292</iyy>
          <izz>0.00625</izz>
        </inertia>
      </inertial>
      <collision name="collision">
        <geometry>
          <!--  ******************col size -->
          <cylinder>
            <radius>0.2</radius>
            <length>0.25</length>
          </cylinder>
        </geometry>
      </collision>
      <visual name="visual">
        <material>
          <ambient>0.03 0.03 0.04 1</ambient>
          <diffuse>0.15 0.15 0.2 1</diffuse>
          <specular>1.0 1.0 1.0 1</specular>
        </material>
        <geometry>
          <!--  ******************vis size-->
          <cylinder>
            <radius>0.2</radius>
            <length>0.25</length>
          </cylinder>
        </geometry>
      </visual>
      <visual name="zmotor">
        <material>
          <ambient>0.03 0.03 0.04 1</ambient>
          <diffuse>0.15 0.15 0.2 1</diffuse>
          <specular>1.0 1.0 1.0 1</specular>
        </material>
        <pose>0 0 0.125 0 0 0</pose>
        <geometry>
          <cylinder>
            <radius>0.25</radius>
            <length>0.05</length>
          </cylinder>
        </geometry>
      </visual>
    </link>

    <!-- Link 1: 50, 2.5m long -->
    <link name="link6">
      <!--
      SDFの<pose>はワールド座標系での位置姿勢を指定します。link1からの相対姿勢を直接指定することはできませんが、<joint>でlink2をlink1に接続し、<pose>を使わずに相対位置は<joint>の<pose>で指定します。link2の<pose>は省略または0にしてください。-->
      <!--  ******************pose -->
      <pose>0 0 7.875 0 0 0</pose>
      <inertial>
        <!--  ******************mass -->
        <mass>50</mass>
        <!--  ******************inertia -->
        <inertia>
          <ixx>0.0292</ixx>
          <iyy>0.0292</iyy>
          <izz>0.00625</izz>
        </inertia>
      </inertial>
      <collision name="collision">
        <pose>0 0 -0.10 0 0 0</pose>
        <geometry>
          <!--  ******************vis size-->
          <box>
            <size>0.6 0.2 0.25
            </size>
          </box>
        </geometry>
      </collision>
      <visual name="base">
        <material>
          <ambient>0.03 0.03 0.04 1</ambient>
          <diffuse>0.15 0.15 0.2 1</diffuse>
          <specular>1.0 1.0 1.0 1</specular>
        </material>
        <pose>0 0 -0.10 0 0 0</pose>
        <geometry>
          <!--  ******************vis size-->
          <box>
            <size>0.6 0.2 0.05
            </size>
          </box>
        </geometry>
      </visual>
      <visual name="hand1">
        <material>
          <ambient>0.03 0.03 0.04 1</ambient>
          <diffuse>0.15 0.15 0.2 1</diffuse>
          <specular>1.0 1.0 1.0 1</specular>
        </material>
        <pose>-0.3 0 0.05 0 0 0</pose>
        <geometry>
          <!--  ******************vis size-->
          <box>
            <size>0.05 0.2 0.4
            </size>
          </box>
        </geometry>
      </visual>
      <visual name="hand2">
        <material>
          <ambient>0.03 0.03 0.04 1</ambient>
          <diffuse>0.15 0.15 0.2 1</diffuse>
          <specular>1.0 1.0 1.0 1</specular>
        </material>
        <pose>0.3 0 0.05 0 0 0</pose>
        <geometry>
          <!--  ******************vis size-->
          <box>
            <size>0.05 0.2 0.4
            </size>
          </box>
        </geometry>
      </visual>
    </link>

    <!-- Joint 0: link0 - link1 -->
    <joint name="joint0" type="revolute">
      <parent>link0</parent>
      <child>link1</child>
      <pose>0 0 -0.125 0 0 0</pose>
      <axis>
        <xyz>0 0 1</xyz>
      </axis>

      <initial_position>2</initial_position>
    </joint>

    <!-- Joint 1: link1 - link2 -->
    <joint name="joint1" type="revolute">
      <parent>link1</parent>
      <child>link2</child>
      <pose>0 0 -1.25 0 0 0</pose>
      <axis>
        <xyz>0 1 0</xyz>
      </axis>
    </joint>

    <!-- Joint 2: link2 - link3 -->
    <joint name="joint2" type="revolute">
      <parent>link2</parent>
      <child>link3</child>
      <pose>0 0 -1.25 0 0 0</pose>
      <axis>
        <xyz>0 1 0</xyz>
      </axis>
    </joint>

    <!-- Joint 3: link3 - link4 -->
    <joint name="joint3" type="revolute">
      <parent>link3</parent>
      <child>link4</child>
      <pose>0 0 -0.25 0 0 0</pose>
      <axis>
        <xyz>0 1 0</xyz>
      </axis>
    </joint>

    <!-- Joint 4: link4 - link5 -->
    <joint name="joint4" type="revolute">
      <parent>link4</parent>
      <child>link5</child>
      <pose>0 0 -0.125 0 0 0</pose>
      <axis>
        <xyz>1 0 0</xyz>
      </axis>
    </joint>

    <!-- Joint 5: link5 - link6 -->
    <joint name="joint5" type="revolute">
      <parent>link5</parent>
      <child>link6</child>
      <pose>0 0 -0.125 0 0 0</pose>
      <axis>
        <xyz>0 0 1</xyz>
      </axis>
    </joint>

    <plugin
      filename="gz-sim-joint-controller-system"
      name="gz::sim::systems::JointController">
      <joint_name>joint0</joint_name>
      <topic>/floating_manipulator/joint0</topic>
      <!--<initial_velocity>1.0</initial_velocity>-->
    </plugin>

    <plugin
      filename="gz-sim-joint-controller-system"
      name="gz::sim::systems::JointController">
      <joint_name>joint1</joint_name>
      <topic>/floating_manipulator/joint1</topic>
      <!--<initial_velocity>1.0</initial_velocity>-->
    </plugin>

    <plugin
      filename="gz-sim-joint-controller-system"
      name="gz::sim::systems::JointController">
      <joint_name>joint2</joint_name>
      <topic>/floating_manipulator/joint2</topic>
      <!--<initial_velocity>1.0</initial_velocity>-->
    </plugin>

    <plugin
      filename="gz-sim-joint-controller-system"
      name="gz::sim::systems::JointController">
      <joint_name>joint3</joint_name>
      <topic>/floating_manipulator/joint3</topic>
      <!--<initial_velocity>1.0</initial_velocity>-->
    </plugin>

    <plugin
      filename="gz-sim-joint-controller-system"
      name="gz::sim::systems::JointController">
      <joint_name>joint4</joint_name>
      <topic>/floating_manipulator/joint4</topic>
      <!--<initial_velocity>1.0</initial_velocity>-->
    </plugin>

    <plugin
      filename="gz-sim-joint-controller-system"
      name="gz::sim::systems::JointController">
      <joint_name>joint5</joint_name>
      <topic>/floating_manipulator/joint5</topic>
      <!--<initial_velocity>1.0</initial_velocity>-->
    </plugin>

  </model>
</sdf>